2020-12-16 21:40:37,980 INFO: Microblog startup [in /mnt/c/Users/atkal/my_projects/microblog/app/__init__.py:42]
2020-12-16 22:01:14,108 INFO: Microblog startup [in /mnt/c/Users/atkal/my_projects/microblog/app/__init__.py:42]
2020-12-16 22:04:31,202 INFO: Microblog startup [in /mnt/c/Users/atkal/my_projects/microblog/app/__init__.py:42]
2020-12-17 10:26:07,895 INFO: Microblog startup [in /mnt/c/Users/atkal/my_projects/microblog/app/__init__.py:42]
2020-12-17 10:26:22,904 INFO: Microblog startup [in /mnt/c/Users/atkal/my_projects/microblog/app/__init__.py:42]
2020-12-17 10:27:04,082 INFO: Microblog startup [in /mnt/c/Users/atkal/my_projects/microblog/app/__init__.py:42]
2020-12-17 10:32:24,232 INFO: Microblog startup [in /mnt/c/Users/atkal/my_projects/microblog/app/__init__.py:42]
2020-12-17 10:55:23,356 INFO: Microblog startup [in /mnt/c/Users/atkal/my_projects/microblog/app/__init__.py:42]
2020-12-17 11:13:40,499 INFO: Microblog startup [in /mnt/c/Users/atkal/my_projects/microblog/app/__init__.py:42]
2020-12-17 15:23:11,827 INFO: Microblog startup [in /mnt/c/Users/atkal/my_projects/microblog/app/__init__.py:42]
2020-12-17 15:24:43,761 ERROR: Exception on /user/Andrey [GET] [in /mnt/c/Users/atkal/my_projects/microblog/.venv/lib/python3.8/site-packages/flask/app.py:1891]
Traceback (most recent call last):
  File "/mnt/c/Users/atkal/my_projects/microblog/.venv/lib/python3.8/site-packages/flask/app.py", line 2447, in wsgi_app
    response = self.full_dispatch_request()
  File "/mnt/c/Users/atkal/my_projects/microblog/.venv/lib/python3.8/site-packages/flask/app.py", line 1952, in full_dispatch_request
    rv = self.handle_user_exception(e)
  File "/mnt/c/Users/atkal/my_projects/microblog/.venv/lib/python3.8/site-packages/flask/app.py", line 1821, in handle_user_exception
    reraise(exc_type, exc_value, tb)
  File "/mnt/c/Users/atkal/my_projects/microblog/.venv/lib/python3.8/site-packages/flask/_compat.py", line 39, in reraise
    raise value
  File "/mnt/c/Users/atkal/my_projects/microblog/.venv/lib/python3.8/site-packages/flask/app.py", line 1950, in full_dispatch_request
    rv = self.dispatch_request()
  File "/mnt/c/Users/atkal/my_projects/microblog/.venv/lib/python3.8/site-packages/flask/app.py", line 1936, in dispatch_request
    return self.view_functions[rule.endpoint](**req.view_args)
  File "/mnt/c/Users/atkal/my_projects/microblog/.venv/lib/python3.8/site-packages/flask_login/utils.py", line 272, in decorated_view
    return func(*args, **kwargs)
  File "/mnt/c/Users/atkal/my_projects/microblog/app/routes.py", line 75, in user
    return render_template('user.html', user = user, posts = posts)
  File "/mnt/c/Users/atkal/my_projects/microblog/.venv/lib/python3.8/site-packages/flask/templating.py", line 137, in render_template
    return _render(
  File "/mnt/c/Users/atkal/my_projects/microblog/.venv/lib/python3.8/site-packages/flask/templating.py", line 120, in _render
    rv = template.render(context)
  File "/mnt/c/Users/atkal/my_projects/microblog/.venv/lib/python3.8/site-packages/jinja2/environment.py", line 1090, in render
    self.environment.handle_exception()
  File "/mnt/c/Users/atkal/my_projects/microblog/.venv/lib/python3.8/site-packages/jinja2/environment.py", line 832, in handle_exception
    reraise(*rewrite_traceback_stack(source=source))
  File "/mnt/c/Users/atkal/my_projects/microblog/.venv/lib/python3.8/site-packages/jinja2/_compat.py", line 28, in reraise
    raise value.with_traceback(tb)
  File "/mnt/c/Users/atkal/my_projects/microblog/app/templates/user.html", line 1, in top-level template code
    {% extends "base.html" %}
  File "/mnt/c/Users/atkal/my_projects/microblog/app/templates/base.html", line 29, in top-level template code
    {% block content %}{% endblock %}
  File "/mnt/c/Users/atkal/my_projects/microblog/app/templates/user.html", line 20, in block "content"
    {{ form.hidden_tag() }}
  File "/mnt/c/Users/atkal/my_projects/microblog/.venv/lib/python3.8/site-packages/jinja2/environment.py", line 471, in getattr
    return getattr(obj, attribute)
jinja2.exceptions.UndefinedError: 'form' is undefined
2020-12-17 15:31:21,074 INFO: Microblog startup [in /mnt/c/Users/atkal/my_projects/microblog/app/__init__.py:42]
2020-12-18 10:55:26,471 INFO: Microblog startup [in /mnt/c/Users/atkal/my_projects/microblog/app/__init__.py:42]
2020-12-18 11:25:16,751 INFO: Microblog startup [in /mnt/c/Users/atkal/my_projects/microblog/app/__init__.py:42]
2020-12-18 11:26:05,324 ERROR: Exception on /index [GET] [in /mnt/c/Users/atkal/my_projects/microblog/.venv/lib/python3.8/site-packages/flask/app.py:1891]
Traceback (most recent call last):
  File "/mnt/c/Users/atkal/my_projects/microblog/.venv/lib/python3.8/site-packages/flask/app.py", line 2447, in wsgi_app
    response = self.full_dispatch_request()
  File "/mnt/c/Users/atkal/my_projects/microblog/.venv/lib/python3.8/site-packages/flask/app.py", line 1952, in full_dispatch_request
    rv = self.handle_user_exception(e)
  File "/mnt/c/Users/atkal/my_projects/microblog/.venv/lib/python3.8/site-packages/flask/app.py", line 1821, in handle_user_exception
    reraise(exc_type, exc_value, tb)
  File "/mnt/c/Users/atkal/my_projects/microblog/.venv/lib/python3.8/site-packages/flask/_compat.py", line 39, in reraise
    raise value
  File "/mnt/c/Users/atkal/my_projects/microblog/.venv/lib/python3.8/site-packages/flask/app.py", line 1950, in full_dispatch_request
    rv = self.dispatch_request()
  File "/mnt/c/Users/atkal/my_projects/microblog/.venv/lib/python3.8/site-packages/flask/app.py", line 1936, in dispatch_request
    return self.view_functions[rule.endpoint](**req.view_args)
  File "/mnt/c/Users/atkal/my_projects/microblog/.venv/lib/python3.8/site-packages/flask_login/utils.py", line 272, in decorated_view
    return func(*args, **kwargs)
  File "/mnt/c/Users/atkal/my_projects/microblog/app/routes.py", line 27, in index
    posts = current_user.followed_posts()
  File "/mnt/c/Users/atkal/my_projects/microblog/app/models.py", line 57, in followed_posts
    followed = Post.query\
  File "/mnt/c/Users/atkal/my_projects/microblog/.venv/lib/python3.8/site-packages/sqlalchemy/orm/query.py", line 2391, in join
    return self._join(
  File "<string>", line 2, in _join
  File "/mnt/c/Users/atkal/my_projects/microblog/.venv/lib/python3.8/site-packages/sqlalchemy/orm/base.py", line 227, in generate
    fn(self, *args[1:], **kw)
  File "/mnt/c/Users/atkal/my_projects/microblog/.venv/lib/python3.8/site-packages/sqlalchemy/orm/query.py", line 2490, in _join
    raise sa_exc.ArgumentError(
sqlalchemy.exc.ArgumentError: Expected mapped entity or selectable/table as join target
2020-12-18 11:27:14,394 INFO: Microblog startup [in /mnt/c/Users/atkal/my_projects/microblog/app/__init__.py:42]
2020-12-18 11:27:18,833 ERROR: Exception on /index [GET] [in /mnt/c/Users/atkal/my_projects/microblog/.venv/lib/python3.8/site-packages/flask/app.py:1891]
Traceback (most recent call last):
  File "/mnt/c/Users/atkal/my_projects/microblog/.venv/lib/python3.8/site-packages/flask/app.py", line 2447, in wsgi_app
    response = self.full_dispatch_request()
  File "/mnt/c/Users/atkal/my_projects/microblog/.venv/lib/python3.8/site-packages/flask/app.py", line 1952, in full_dispatch_request
    rv = self.handle_user_exception(e)
  File "/mnt/c/Users/atkal/my_projects/microblog/.venv/lib/python3.8/site-packages/flask/app.py", line 1821, in handle_user_exception
    reraise(exc_type, exc_value, tb)
  File "/mnt/c/Users/atkal/my_projects/microblog/.venv/lib/python3.8/site-packages/flask/_compat.py", line 39, in reraise
    raise value
  File "/mnt/c/Users/atkal/my_projects/microblog/.venv/lib/python3.8/site-packages/flask/app.py", line 1950, in full_dispatch_request
    rv = self.dispatch_request()
  File "/mnt/c/Users/atkal/my_projects/microblog/.venv/lib/python3.8/site-packages/flask/app.py", line 1936, in dispatch_request
    return self.view_functions[rule.endpoint](**req.view_args)
  File "/mnt/c/Users/atkal/my_projects/microblog/.venv/lib/python3.8/site-packages/flask_login/utils.py", line 272, in decorated_view
    return func(*args, **kwargs)
  File "/mnt/c/Users/atkal/my_projects/microblog/app/routes.py", line 27, in index
    posts = current_user.followed_posts().all()
  File "/mnt/c/Users/atkal/my_projects/microblog/app/models.py", line 57, in followed_posts
    followed = Post.query\
  File "/mnt/c/Users/atkal/my_projects/microblog/.venv/lib/python3.8/site-packages/sqlalchemy/orm/query.py", line 2391, in join
    return self._join(
  File "<string>", line 2, in _join
  File "/mnt/c/Users/atkal/my_projects/microblog/.venv/lib/python3.8/site-packages/sqlalchemy/orm/base.py", line 227, in generate
    fn(self, *args[1:], **kw)
  File "/mnt/c/Users/atkal/my_projects/microblog/.venv/lib/python3.8/site-packages/sqlalchemy/orm/query.py", line 2490, in _join
    raise sa_exc.ArgumentError(
sqlalchemy.exc.ArgumentError: Expected mapped entity or selectable/table as join target
