2020-12-18 11:27:36,534 ERROR: Exception on /index [GET] [in /mnt/c/Users/atkal/my_projects/microblog/.venv/lib/python3.8/site-packages/flask/app.py:1891]
Traceback (most recent call last):
  File "/mnt/c/Users/atkal/my_projects/microblog/.venv/lib/python3.8/site-packages/flask/app.py", line 2447, in wsgi_app
    response = self.full_dispatch_request()
  File "/mnt/c/Users/atkal/my_projects/microblog/.venv/lib/python3.8/site-packages/flask/app.py", line 1952, in full_dispatch_request
    rv = self.handle_user_exception(e)
  File "/mnt/c/Users/atkal/my_projects/microblog/.venv/lib/python3.8/site-packages/flask/app.py", line 1821, in handle_user_exception
    reraise(exc_type, exc_value, tb)
  File "/mnt/c/Users/atkal/my_projects/microblog/.venv/lib/python3.8/site-packages/flask/_compat.py", line 39, in reraise
    raise value
  File "/mnt/c/Users/atkal/my_projects/microblog/.venv/lib/python3.8/site-packages/flask/app.py", line 1950, in full_dispatch_request
    rv = self.dispatch_request()
  File "/mnt/c/Users/atkal/my_projects/microblog/.venv/lib/python3.8/site-packages/flask/app.py", line 1936, in dispatch_request
    return self.view_functions[rule.endpoint](**req.view_args)
  File "/mnt/c/Users/atkal/my_projects/microblog/.venv/lib/python3.8/site-packages/flask_login/utils.py", line 272, in decorated_view
    return func(*args, **kwargs)
  File "/mnt/c/Users/atkal/my_projects/microblog/app/routes.py", line 27, in index
    posts = current_user.followed_posts().all()
  File "/mnt/c/Users/atkal/my_projects/microblog/app/models.py", line 57, in followed_posts
    followed = Post.query\
  File "/mnt/c/Users/atkal/my_projects/microblog/.venv/lib/python3.8/site-packages/sqlalchemy/orm/query.py", line 2391, in join
    return self._join(
  File "<string>", line 2, in _join
  File "/mnt/c/Users/atkal/my_projects/microblog/.venv/lib/python3.8/site-packages/sqlalchemy/orm/base.py", line 227, in generate
    fn(self, *args[1:], **kw)
  File "/mnt/c/Users/atkal/my_projects/microblog/.venv/lib/python3.8/site-packages/sqlalchemy/orm/query.py", line 2490, in _join
    raise sa_exc.ArgumentError(
sqlalchemy.exc.ArgumentError: Expected mapped entity or selectable/table as join target
2020-12-18 11:34:06,070 INFO: Microblog startup [in /mnt/c/Users/atkal/my_projects/microblog/app/__init__.py:42]
